2024-08-04 19:59:11 | ERROR | Traceback (most recent call last):
  File "/home/d2023f/Documentos/Programaci√≥n/Eje/Social-Friendly-/api/src/routes/Files/CreateUserDirectory.py", line 24, in create_directory
    os.mkdir(path)
FileExistsError: [Errno 17] File exists: 'images/@isaacn'

